<?xml version="1.0"?>
<!--
  robot.urdf.xacro
  ~~~~~~~~~~~~~~~~
  4-wheel skid-steer competition robot
  • 4 independent DC motors (TB6612FNG × 2)
  • 2D LiDAR (RPLidar A1/A2 style) on top
  • IMU (on base_link)
  • 2× paddle servo links (left / right)
  • 1× crank servo link (front-center)

  Coordinate convention (REP-103):
    x = forward,  y = left,  z = up
-->
<robot xmlns:xacro="http://www.ros.org/wiki/xacro" name="competition_robot">

  <!-- ══════════════════════════════════════════════════════════════════
       Parameters — tune to match your 3D-printed chassis
  ══════════════════════════════════════════════════════════════════ -->
  <xacro:property name="base_length"       value="0.30"/>
  <xacro:property name="base_width"        value="0.25"/>
  <xacro:property name="base_height"       value="0.08"/>
  <xacro:property name="base_mass"         value="3.0"/>

  <xacro:property name="wheel_radius"      value="0.045"/>
  <xacro:property name="wheel_width"       value="0.03"/>
  <xacro:property name="wheel_mass"        value="0.2"/>
  <!-- longitudinal (x) and lateral (y) offset from base centre to wheel -->
  <xacro:property name="wheel_x_offset"    value="0.10"/>
  <xacro:property name="wheel_y_offset"    value="0.145"/>

  <!-- Servo arm link dimensions (3D-printed) -->
  <xacro:property name="paddle_length"     value="0.08"/>
  <xacro:property name="paddle_width"      value="0.015"/>
  <xacro:property name="paddle_height"     value="0.06"/>
  <xacro:property name="crank_length"      value="0.06"/>
  <xacro:property name="crank_radius"      value="0.01"/>

  <!-- ══════════════════════════════════════════════════════════════════
       Inertia helpers
  ══════════════════════════════════════════════════════════════════ -->
  <xacro:macro name="box_inertia" params="m w h d">
    <inertial>
      <mass value="${m}"/>
      <inertia
        ixx="${m*(h*h+d*d)/12}" ixy="0" ixz="0"
        iyy="${m*(w*w+d*d)/12}" iyz="0"
        izz="${m*(w*w+h*h)/12}"/>
    </inertial>
  </xacro:macro>

  <xacro:macro name="cylinder_inertia" params="m r l">
    <inertial>
      <mass value="${m}"/>
      <inertia
        ixx="${m*(3*r*r+l*l)/12}" ixy="0" ixz="0"
        iyy="${m*(3*r*r+l*l)/12}" iyz="0"
        izz="${m*r*r/2}"/>
    </inertial>
  </xacro:macro>

  <!-- ══════════════════════════════════════════════════════════════════
       Base
  ══════════════════════════════════════════════════════════════════ -->
  <link name="base_footprint"/>

  <joint name="base_footprint_joint" type="fixed">
    <parent link="base_footprint"/>
    <child  link="base_link"/>
    <origin xyz="0 0 ${wheel_radius}" rpy="0 0 0"/>
  </joint>

  <link name="base_link">
    <visual>
      <geometry><box size="${base_length} ${base_width} ${base_height}"/></geometry>
      <material name="dark_grey"><color rgba="0.2 0.2 0.2 1"/></material>
    </visual>
    <collision>
      <geometry><box size="${base_length} ${base_width} ${base_height}"/></geometry>
    </collision>
    <xacro:box_inertia m="${base_mass}" w="${base_width}" h="${base_height}" d="${base_length}"/>
  </link>

  <!-- ══════════════════════════════════════════════════════════════════
       Wheel macro  (name = fl | fr | rl | rr)
  ══════════════════════════════════════════════════════════════════ -->
  <xacro:macro name="wheel" params="name x_sign y_sign">
    <link name="${name}_wheel">
      <visual>
        <geometry><cylinder radius="${wheel_radius}" length="${wheel_width}"/></geometry>
        <material name="black"><color rgba="0.05 0.05 0.05 1"/></material>
      </visual>
      <collision>
        <geometry><cylinder radius="${wheel_radius}" length="${wheel_width}"/></geometry>
      </collision>
      <xacro:cylinder_inertia m="${wheel_mass}" r="${wheel_radius}" l="${wheel_width}"/>
    </link>

    <joint name="${name}_wheel_joint" type="continuous">
      <parent link="base_link"/>
      <child  link="${name}_wheel"/>
      <origin
        xyz="${x_sign * wheel_x_offset} ${y_sign * wheel_y_offset} 0"
        rpy="${-pi/2} 0 0"/>
      <axis xyz="0 0 1"/>
    </joint>
  </xacro:macro>

  <!-- 4 independent wheels -->
  <xacro:wheel name="fl" x_sign="1"  y_sign="1"/>
  <xacro:wheel name="fr" x_sign="1"  y_sign="-1"/>
  <xacro:wheel name="rl" x_sign="-1" y_sign="1"/>
  <xacro:wheel name="rr" x_sign="-1" y_sign="-1"/>

  <!-- ══════════════════════════════════════════════════════════════════
       LiDAR
  ══════════════════════════════════════════════════════════════════ -->
  <link name="lidar_link">
    <visual>
      <geometry><cylinder radius="0.035" length="0.055"/></geometry>
      <material name="blue"><color rgba="0.0 0.3 0.8 1"/></material>
    </visual>
    <collision>
      <geometry><cylinder radius="0.035" length="0.055"/></geometry>
    </collision>
    <inertial>
      <mass value="0.17"/>
      <inertia ixx="0.0001" ixy="0" ixz="0" iyy="0.0001" iyz="0" izz="0.0001"/>
    </inertial>
  </link>

  <joint name="lidar_joint" type="fixed">
    <parent link="base_link"/>
    <child  link="lidar_link"/>
    <!-- Mounted centred on top of chassis -->
    <origin xyz="0 0 ${base_height/2 + 0.03}" rpy="0 0 0"/>
  </joint>

  <!-- LiDAR Gazebo plugin -->
  <gazebo reference="lidar_link">
    <sensor name="lidar" type="ray">
      <always_on>true</always_on>
      <update_rate>10</update_rate>
      <visualize>true</visualize>
      <ray>
        <scan>
          <horizontal>
            <samples>360</samples>
            <resolution>1</resolution>
            <min_angle>-3.14159265</min_angle>
            <max_angle>3.14159265</max_angle>
          </horizontal>
        </scan>
        <range>
          <min>0.15</min>
          <max>8.0</max>
          <resolution>0.01</resolution>
        </range>
        <noise>
          <type>gaussian</type>
          <mean>0.0</mean>
          <stddev>0.01</stddev>
        </noise>
      </ray>
      <plugin name="lidar_plugin" filename="libgazebo_ros_ray_sensor.so">
        <ros>
          <remapping>~/out:=/scan</remapping>
        </ros>
        <output_type>sensor_msgs/LaserScan</output_type>
        <frame_name>lidar_link</frame_name>
      </plugin>
    </sensor>
  </gazebo>

  <!-- ══════════════════════════════════════════════════════════════════
       IMU
  ══════════════════════════════════════════════════════════════════ -->
  <link name="imu_link"/>
  <joint name="imu_joint" type="fixed">
    <parent link="base_link"/>
    <child  link="imu_link"/>
    <origin xyz="0 0 0" rpy="0 0 0"/>
  </joint>

  <gazebo reference="imu_link">
    <sensor name="imu_sensor" type="imu">
      <always_on>true</always_on>
      <update_rate>100</update_rate>
      <plugin name="imu_plugin" filename="libgazebo_ros_imu_sensor.so">
        <ros><remapping>~/out:=/imu/data</remapping></ros>
        <frame_name>imu_link</frame_name>
      </plugin>
    </sensor>
  </gazebo>

  <!-- ══════════════════════════════════════════════════════════════════
       Paddle servo effectors  (left + right, mounted rear sides)
  ══════════════════════════════════════════════════════════════════ -->
  <xacro:macro name="paddle" params="name y_sign">
    <!-- Servo body (fixed to chassis) -->
    <link name="${name}_servo_body">
      <visual>
        <geometry><box size="0.023 0.012 0.028"/></geometry>
        <material name="servo_grey"><color rgba="0.3 0.3 0.3 1"/></material>
      </visual>
    </link>
    <joint name="${name}_servo_body_joint" type="fixed">
      <parent link="base_link"/>
      <child  link="${name}_servo_body"/>
      <origin xyz="${-base_length/2 + 0.04} ${y_sign * (base_width/2 + 0.015)} ${base_height/4}" rpy="0 0 0"/>
    </joint>

    <!-- Paddle arm (revolute — rotates around Z) -->
    <link name="${name}_paddle">
      <visual>
        <origin xyz="${paddle_length/2} 0 0" rpy="0 0 0"/>
        <geometry><box size="${paddle_length} ${paddle_width} ${paddle_height}"/></geometry>
        <material name="orange"><color rgba="1.0 0.5 0.0 1"/></material>
      </visual>
      <collision>
        <origin xyz="${paddle_length/2} 0 0" rpy="0 0 0"/>
        <geometry><box size="${paddle_length} ${paddle_width} ${paddle_height}"/></geometry>
      </collision>
      <inertial>
        <mass value="0.03"/>
        <inertia ixx="0.00001" ixy="0" ixz="0" iyy="0.00001" iyz="0" izz="0.00001"/>
      </inertial>
    </link>
    <joint name="${name}_paddle_joint" type="revolute">
      <parent link="${name}_servo_body"/>
      <child  link="${name}_paddle"/>
      <origin xyz="0 0 0.015" rpy="0 0 0"/>
      <axis xyz="0 0 1"/>
      <limit lower="-1.5708" upper="1.5708" effort="0.5" velocity="3.0"/>
    </joint>
  </xacro:macro>

  <xacro:paddle name="left_paddle"  y_sign="1"/>
  <xacro:paddle name="right_paddle" y_sign="-1"/>

  <!-- ══════════════════════════════════════════════════════════════════
       Crank servo effector  (front-centre, mounted forward)
  ══════════════════════════════════════════════════════════════════ -->
  <link name="crank_servo_body">
    <visual>
      <geometry><box size="0.023 0.012 0.028"/></geometry>
      <material name="servo_grey"><color rgba="0.3 0.3 0.3 1"/></material>
    </visual>
  </link>
  <joint name="crank_servo_body_joint" type="fixed">
    <parent link="base_link"/>
    <child  link="crank_servo_body"/>
    <origin xyz="${base_length/2 - 0.02} 0 ${base_height/4}" rpy="0 0 0"/>
  </joint>

  <link name="crank_arm">
    <visual>
      <origin xyz="0 0 ${crank_length/2}" rpy="0 0 0"/>
      <geometry><cylinder radius="${crank_radius}" length="${crank_length}"/></geometry>
      <material name="orange"><color rgba="1.0 0.5 0.0 1"/></material>
    </visual>
    <collision>
      <origin xyz="0 0 ${crank_length/2}" rpy="0 0 0"/>
      <geometry><cylinder radius="${crank_radius}" length="${crank_length}"/></geometry>
    </collision>
    <inertial>
      <mass value="0.02"/>
      <inertia ixx="0.000005" ixy="0" ixz="0" iyy="0.000005" iyz="0" izz="0.000005"/>
    </inertial>
  </link>
  <joint name="crank_joint" type="revolute">
    <parent link="crank_servo_body"/>
    <child  link="crank_arm"/>
    <origin xyz="0 0 0.015" rpy="0 0 0"/>
    <axis xyz="1 0 0"/>
    <limit lower="0" upper="3.14159" effort="0.5" velocity="3.0"/>
  </joint>

  <!-- ══════════════════════════════════════════════════════════════════
       Gazebo — skid-steer drive plugin (4-wheel)
  ══════════════════════════════════════════════════════════════════ -->
  <gazebo>
    <plugin name="skid_steer_drive" filename="libgazebo_ros_diff_drive.so">
      <!-- Skid steer: treat left pair and right pair as two virtual axles -->
      <left_joint>fl_wheel_joint</left_joint>
      <right_joint>fr_wheel_joint</right_joint>
      <wheel_separation>${wheel_y_offset * 2}</wheel_separation>
      <wheel_diameter>${2 * wheel_radius}</wheel_diameter>
      <max_wheel_torque>10</max_wheel_torque>
      <max_wheel_acceleration>2.0</max_wheel_acceleration>
      <command_topic>cmd_vel</command_topic>
      <publish_odom>true</publish_odom>
      <publish_odom_tf>true</publish_odom_tf>
      <odometry_topic>odom</odometry_topic>
      <odometry_frame>odom</odometry_frame>
      <robot_base_frame>base_footprint</robot_base_frame>
    </plugin>
  </gazebo>

  <!-- Rear wheel friction (skid steer passive) -->
  <gazebo reference="rl_wheel">
    <mu1>0.5</mu1><mu2>0.5</mu2>
  </gazebo>
  <gazebo reference="rr_wheel">
    <mu1>0.5</mu1><mu2>0.5</mu2>
  </gazebo>

</robot>
